Workbook

Sheet 项目目录
A1: 聚杰减碳项目收集表 - 排放源目录
A2: 实际年产值 | B2: 6770.81 | C2: 万美金 | D2: 美金汇率： | E2: 7.1 | F2: （2025年12月31日） | G2: 填报年产值 | H2: 8500
A3: 博世(财务实际数值） | B3: 2051.48 | C3: 万美金 | D3: 以7.1汇率来计算
A4: 百得（财务实际数值） | B4: 265.66 | C4: 万美金
A5: 类别 | B5: 排放源类型 | C5: 具体项目 | D5: 单位 | E5: 责任人 | F5: 数据来源 | G5: 2025年数据 | H5: 碳排放数据（tCOe） | I5: 计算公式（排放因子取数基于GHG Protocol体系） | J5: 解析
A6: 类别一 | B6: 固定源 | C6: 天然气炉灶 | D6: Nm³ | E6: 应卫 | F6: 天然气用量统计表、发票 | G6: 0 | H6: 0 | I6: 排放量 = 年天然气消耗量 (Nm³) ×排放因子（2.16 kgCO₂/Nm³）÷1000
A7: 类别一 | B7: 固定源 | C7: 液化石油气炉灶 | D7: 升 | E7: 应卫 | F7: 液化石油气用量统计表、发票 | G7: =液化石油气!B17 -> 8430.8824 | H7: =G7*K7*M7/1000 -> 14.113297 | I7: 排放量 = 液化石油气消耗量 (L) ×液态液化石油气密度（0.54 (kg/L) ×3.10 (kgCO₂/kg‑LPG)÷1000 | J7: 液化石油密度 | K7: 0.54 | L7: EFLpG | M7: 3.1
A8: 类别一 | B8: 移动源 | C8: 货车（柴油） | D8: 升 | E8: 财务 | F8: 柴油用量、油卡导出数据 | G8: ='中国石化柴汽油-汇总 '!D13 -> 4106.76 | H8: =G8*K8/1000 -> 10.800779 | I8: 排放量 = 燃油消耗量 (L) × 排放因子 (2.63 kgCO₂e / L) ÷1000 | J8: 柴油排放因子 | K8: 2.63
A9: 类别一 | B9: 移动源 | C9: 小汽车（汽油） | D9: 升 | E9: 财务 | F9: 汽油用量、油卡导出数据 | G9: ='中国石化柴汽油-汇总 '!D7 -> 19158.29 | H9: =G9*K9/1000 -> 43.297735 | I9: 排放量 = 燃油消耗量 (L) × 排放因子 (2.26 kgCO₂e/L) ÷1000 | J9: 汽油排放因子 | K9: 2.26
A10: 类别一 | B10: 工艺制程 | C10: 防锈漆 | E10: 马进军 | F10: 化学品清单、用量统计 | G10: 无
A11: 类别一 | B11: 工艺制程 | C11: 自喷漆 | E11: 马进军 | F11: 化学品清单、用量统计
A12: 类别一 | B12: 工艺制程 | C12: 清洗剂 | E12: 马进军 | F12: 化学品清单、用量统计
A13: 类别一 | B13: 逸散源 | C13: 灭火器（二氧化碳） | D13: 千克 | E13: 应卫 | F13: 消防设备清单、年度增减数量 | G13: 0 | H13: 0 | I13: 排放量=当年补充安装CO₂（kg）×1（GWP(CO₂)） ÷1000
A14: 类别一 | B14: 逸散源 | C14: 制冷剂（办公空调） | D14: 千克 | E14: 应卫 | F14: 空调设备铭牌、制冷剂型号、额定填充量 | G14: ='空调制冷剂（办公）'!G19 -> 90 | H14: =G14*O14/1000 -> 60.75 | I14: 排放量=当年补充加注制冷剂(kg)×该冷媒GWP值÷1000 | J14: R134a | K14: 1430 | L14: R410A | M14: 2088 | N14: R‑32 | O14: 675
A15: 类别一 | B15: 逸散源 | C15: 制冷剂（生产设备） | D15: 千克 | E15: 李贵 | F15: 空压机、生产设备铭牌、制冷剂型号 | G15: ='制冷剂设备明细（生产）'!F8 -> 4.5 | H15: =G15*M14/1000 -> 9.396 | J15: R407C | K15: 1774 | L15: R22 | M15: 1810
A16: 类别一 | B16: 逸散源 | C16: 厂区化粪池 | D16: 人 | E16: 应卫 | F16: 统计1-12月份月在岗人数，取平均值，得出平均在岗人数，既当量人口 | G16: =化粪池工时!E4 -> 890 | H16: =G16*K16/1000 -> 155.75 | I16: 排放量 = 当量人口 × 排放因子（175 kgCO₂e/EP・a） ÷1000 | J16: 人均排放因子 | K16: 175
A17: 类别二 | B17: 外购电力 | C17: 全厂用电量 | D17: 千瓦时 | E17: 应卫 | F17: 全年总用电量，减去租赁部分，减太阳能光伏，得出实际产碳的全厂用电量 | G17: =用电量统计!G47 -> 3340189.6 | H17: =G17*K17 -> 1947.3305 | I17: 排放量= 年度总用电量 (kWh) × 0.000583 （浙江省级电网排放因子 (tCO₂e/kWh)） | J17: 浙江省级电网排放因子 | K17: 0.000583
A18: 类别三 | B18: 交通运输 | C18: 成品运输 | D18: 吨/公里 | E18: 谢荣浩 | F18: 公司到港口，对应具体客户 | G18: ='成品运输-汇总'!B12 -> 2323003.2 | H18: =G18*K18 -> 197.45527 | I18: 排放量= 总运输周转量 (t・km) × 0.000085 货物运输排放因子 (tCO₂e /t・km) | J18: 货物运输排放因子 | K18: 8.5e-05
A19: 类别三 | B19: 出差 | C19: 私车公用 | D19: 升 | E19: 应卫 | F19: 私车公用补贴公里数 | G19: =私车公用!O42 -> 15504.127 | H19: =G19*K19/1000 -> 35.039328 | I19: 排放量= 私车公务燃油消耗量 (L) × 2.26 （汽油排放因子 (kgCO₂e/L)） ÷1000 | J19: 汽油排放因子 | K19: 2.26

Sheet 计算方式
A1: 排放源类型 | B1: 具体项目 | C1: 单位 | D1: 计算说明 | E1: 计算公式
A2: 固定源 | B2: 天然气炉灶 | C2: Nm³（标准立方米） | D2: =_xlfn.DISPIMG("ID_C2C558BC60FF4A17B18FE056CA7720BD",1) -> =DISPIMG("ID_C2C558BC60FF4A17B18FE056CA7720BD",1) | E2: 排放量 = 年天然气消耗量 (Nm³) ×排放因子（2.16 kgCO₂/Nm³）÷1000
B3: 液化石油气炉灶 | C3: L（升） | D3: =_xlfn.DISPIMG("ID_A74A31E412A04ABE810B17CA1DF3E20A",1) -> =DISPIMG("ID_A74A31E412A04ABE810B17CA1DF3E20A",1) | E3: 排放量 = 液化石油气消耗量 (L) ×液态液化石油气密度0.54 (kg/L) ×3.10 (kgCO₂/kg‑LPG)÷1000
A4: 移动源 | B4: 货车（柴油） | C4: L（升） | D4: =_xlfn.DISPIMG("ID_253465B3915F40368BB06253CD4B4B55",1) -> =DISPIMG("ID_253465B3915F40368BB06253CD4B4B55",1) | E4: 排放量 = 燃油消耗量 (L) × 排放因子 (2.63 kgCO₂e / L) ÷1000
B5: 小汽车（汽油） | C5: L（升） | E5: 排放量 = 燃油消耗量 (L) × 排放因子 (2.26 kgCO₂e/L) ÷1000
A6: 逸散源 | B6: 灭火器（二氧化碳） | C6: kg（千克） | D6: =_xlfn.DISPIMG("ID_5CFECD97F0CE43E1AFE90D5B0F1C019C",1) -> =DISPIMG("ID_5CFECD97F0CE43E1AFE90D5B0F1C019C",1) | E6: 排放量=当年补充安装CO₂（kg）×1（GWP(CO₂)） ÷1000
B7: 制冷剂（办公空调） | C7: kg（千克） | D7: =_xlfn.DISPIMG("ID_9D57645565284682936573C2E426EC9D",1) -> =DISPIMG("ID_9D57645565284682936573C2E426EC9D",1) | E7: 排放量=当年补充加注制冷剂(kg)×该冷媒GWP÷1000
B8: 制冷剂（生产设备） | C8: kg（千克）
B9: 厂区化粪池 | C9: 人 | D9: =_xlfn.DISPIMG("ID_FC6525F5A09C4696AA232F3FA5B32ADD",1) -> =DISPIMG("ID_FC6525F5A09C4696AA232F3FA5B32ADD",1) | E9: 排放量 = 当量人口 × 排放因子（175 kgCO₂e/EP・a） ÷1000
A10: 外购电力 | B10: 全场用电量 | C10: 千瓦时 | D10: =_xlfn.DISPIMG("ID_7ED23A6C11FF47DBA9176B0B21884725",1) -> =DISPIMG("ID_7ED23A6C11FF47DBA9176B0B21884725",1) | E10: 排放量= 年度总用电量 (kWh) × 0.000583浙江省级电网排放因子 (tCO₂e/kWh)
A11: 交通运输 | B11: 成品运输 | C11: 吨/公里 | D11: =_xlfn.DISPIMG("ID_1456CD8EBC0C40998D056FDA023A90A6",1) -> =DISPIMG("ID_1456CD8EBC0C40998D056FDA023A90A6",1) | E11: 排放量= 总运输周转量 (t・km) × 货物运输排放因子 (tCO₂e /t・km) 公路货运因子：0.000085 tCO₂e / t·km
A12: 出差 | B12: 私车公用 | C12: L（升） | D12: =_xlfn.DISPIMG("ID_850E3306AB454135A658D6130B5ABDDA",1) -> =DISPIMG("ID_850E3306AB454135A658D6130B5ABDDA",1) | E12: 排放量= 私车公务燃油消耗量 (L) × 汽油排放因子 (kgCO₂e/L) ÷1000 汽油因子： 2.26 kgCO₂e/L

Sheet 天然气
A1: 天然气用量统计表
A2: 月份 | B2: 2021年 | C2: 2022年 | D2: 2023年 | E2: 2024年 | F2: 2025年
A3: 1月 | B3: 5750 | C3: 5708 | E3: 6470
A4: 2月 | B4: 2479 | C4: 1430 | E4: 1008
A5: 3月 | B5: 2414 | C5: 4915 | E5: 6155
A6: 4月 | B6: 5968 | C6: 6006 | E6: 7153
A7: 5月 | B7: 5684 | C7: 5358 | E7: 5717
A8: 6月 | B8: 5357 | C8: 5004 | E8: 6291
A9: 7月 | B9: 6722 | C9: 4237 | E9: 3311
A10: 8月 | B10: 5602 | C10: 5794 | E10: 5488
A11: 9月 | B11: 5346 | C11: 4421 | E11: 4613
A12: 10月 | B12: 3670 | C12: 4112 | E12: 4397
A13: 11月 | B13: 5069 | C13: 4522 | E13: 5265
A14: 12月 | B14: 4862 | C14: 7439 | E14: 5876
A15: 合计 | B15: 58923 | C15: 51507 | E15: 61744
A17: 备注：生产公益改进，新工艺无天然气使用需求，不再统计数据。

Sheet 液化石油气
A1: 液化石油气用量统计表
A2: 一、按升计量（油量/金额）---生物燃油（燃料油）
A3: 月份 | B3: 2025年 | D3: 2026年 | F3: 2027年 | H3: 2028年
B4: 油量（升） | C4: 金额（元） | D4: 油量（升） | E4: 金额（元） | F4: 油量（升） | G4: 金额（元） | H4: 油量（升） | I4: 金额（元）
A5: 1月 | B5: 848.52941 | C5: 5770
A6: 2月 | B6: 414.70588 | C6: 2820
A7: 3月 | B7: 816.17647 | C7: 5550
A8: 4月 | B8: 1132.3529 | C8: 7700
A9: 5月 | B9: 426.47059 | C9: 2900
A10: 6月 | B10: 851.47059 | C10: 5790
A11: 7月 | B11: 791.17647 | C11: 5380
A12: 8月 | B12: 441.17647 | C12: 3000
A13: 9月 | B13: 817.64706 | C13: 5560
A14: 10月 | B14: 794.11765 | C14: 5400
A15: 11月 | B15: 747.05882 | C15: 5080
A16: 12月 | B16: 350 | C16: 2380
A17: 合计 | B17: 8430.8824 | C17: 68735

Sheet 中国石化柴汽油明细
A1: 中国石化加油IC卡台账对账单 O0EC 客户名称：金华市聚杰电器有限公司 账户号：0n330200561385 起止时间：2025-01-01至2025-12-31 网点名称：金武义城西加油站 主卡卡号：1000113300020795084
A3: 卡号：1000113300020795084 | C3: 持卡人：童碧君 | H3: 限车号：
A4: 账单类型： 备付账 卡账 ☐钱包账 | H4: 账户类型： 资金账户 ☐优惠账户
A5: 时间 | B5: 业务类型 | C5: 品种 | D5: 数量 | E5: 单价 | F5: 交易金额 | G5: 卡钱包 | H5: 网点名称 | I5: 油站地址 | J5: 备注
A6: 2025-01-06 10:47:42 | B6: 充值 | C6: * | D6: 0 | E6: 0 | F6: 10000 | G6: 0 | H6: 到账微信线上充值 | I6: 杭州市河坊街58号
A7: 2025-01-06 10:48:03 | B7: 充值 | C7: * | D7: 0 | E7: 0 00 | F7: 10600 | G7: 0 | H7: 到账微信线上充值 | I7: 杭州市河坊街58号
A8: 2025-01-09 09:17:01 | B8: 充值 | C8: * | D8: 0 | E8: 0 | F8: 10000 | G8: 0 | H8: 到账微信线上充值 | I8: 杭州市河坊街58号
A9: 2025-01-11 10:00:45 | B9: 补卡转账 | C9: 후 | D9: 0 | E9: 0 | F9: 1952.04 | G9: 0 | H9: 浙江省管理中心
A10: 2025-01-11 17:29:28 | B10: 圈存 | C10: 9 | D10: 0 | E10: 0 | F10: 1952.04 | G10: 2874 47 | H10: 金武义城北加油站 | I10: 武义县武阳镇毛衣弄口
A11: 2025-01-11 17:29:37 | B11: 加油 | C11: 92号车用汽油(VIB) | D11: 40.17 | E11: 7.47 | F11: 300 | G11: 2574.47 | H11: 金武义城北加油站 | I11: 武义县武阳镇毛衣弄口
A12: 2025-01-26 14:43:30 | B12: 充值 | C12: * | D12: 0 | E12: 0 | F12: 9600 | G12: 0 | H12: 到账微信线上充值 | I12: 杭州市河坊街58号
A13: 2025-02-14 18:52:18 | B13: 充值 | C13: * | D13: 0 | E13: 0 00 | F13: 10000 00 | G13: 0 00 | H13: 到账微信线上充值 | I13: 杭州市河坊街58号
A14: 2025-03-07 14:40:14 | B14: 充值 | C14: 称 | D14: 0 | E14: 0 | F14: 8600 | G14: 0 00 | H14: 到账微信线上充值 | I14: 杭州市河坊街58号
A15: 2025-04-02 16:42:20 | B15: 充值 | C15: * | D15: 0 | E15: 0 | F15: 9600 | G15: 0 | H15: 到账微信线上充值 | I15: 杭州市河坊街58号
A16: 2025-05-08 13:33:45 | B16: 充值 | C16: * | D16: 0 | E16: 0 00 | F16: 9600 | G16: 0 | H16: 到账微信线上充值 | I16: 杭州市河坊街58号
A17: 2025-05-08 13:34:12 | B17: 充值 | C17: * | D17: 0 | E17: 0 | F17: 5000 | G17: 0 | H17: 到账微信线上充值 | I17: 杭州市河坊街58号
A18: 2025-06-05 15:37:52 | B18: 充值 | C18: * | D18: 0 | E18: 000 | F18: 9600 | G18: 0 | H18: 到账微信线上充值 | I18: 杭州市河坊街58号
A19: 2025-06-17 08:55:46 | B19: 充值 | C19: * | D19: 0 | E19: 0 | F19: 20000 | G19: 0 | H19: 到账微信线上充值 | I19: 杭州市河坊街58号
A20: 2025-07-16 09:20:31 | B20: 充值 | C20: * | D20: 0 | E20: 0 | F20: 10000 | G20: 0 | H20: 到账微信线上充值 | I20: 杭州市河坊街58号
A21: 2025-07-21 09:34:18 | B21: 充值 | C21: 称 | D21: 0 | E21: 0 | F21: 9600 | G21: 0 | H21: 到账微信线上充值 | I21: 杭州市河坊街58号
A22: 2025-08-05 11:01:29 | B22: 充值 | C22: * | D22: 0 | E22: 0 | F22: 9600 | G22: 0 | H22: 到账微信线上充值 | I22: 杭州市河坊街58号
A23: 2025-09-01 09:01:57 | B23: 充值 | C23: * | D23: 0 | E23: 0 | F23: 9600 | G23: 0 | H23: 到账微信线上充值 | I23: 杭州市河坊街58号
A24: 2025-09-24 08:56:03 | B24: 充值 | C24: * | D24: 0 | E24: 0 | F24: 10000 | G24: 0 | H24: 到账微信线上充值 | I24: 杭州市河坊街58号
A25: 2025-10-10 19:52:02 | B25: 充值 | C25: * | D25: 0 | E25: 0 | F25: 9600 | G25: 0 | H25: 到账微信线上充值 | I25: 杭州市河坊街58号
A26: 2025-11-04 16:04:44 | B26: 充值 | C26: * | D26: 0 | E26: 0 | F26: 9600 00 | G26: 0 | H26: 到账微信线上充值 | I26: 杭州市河坊街58号
A27: 2025-11-29 08:36:34 | B27: 充值 | C27: * | D27: 0 | E27: 0 00 | F27: 9600 | G27: 0 | H27: 到账微信线上充值 | I27: 杭州市河坊街58号
A28: 2025-12-10 10:05:24 | B28: 充值 | C28: * | D28: 0 | E28: 0 | F28: 10000 | G28: 0 | H28: 到账微信线上充值 | I28: 杭州市河坊街58号
A29: 2025-12-31 12:57:14 | B29: 充值 | C29: * | D29: 0 | E29: 0 | F29: 9100 | G29: 0 | H29: 到账微信线上充值 | I29: 杭州市河坊街58号
A30: 分项小计 充值：209.300元 预分配：0元 圈存：1.952.04元 圈提：0元 消费：300元 数量：40.17 优惠返利：0元 明折明扣：0元
A31: 卡号：1000113300020795085 | C31: 持卡人：童碧君 | H31: 限车号：
A32: 账单类型： 备付账 卡账 ☐钱包账 | H32: 账户类型： 资金账户 ☐优惠账户
A33: 时间 | B33: 业务类型 | C33: 品种 | D33: 数量 | E33: 单价 | F33: 交易金额 | G33: 卡钱包 | H33: 网点名称 | I33: 油站地址 | J33: 备注
A34: 2025-01-09 22:07:31 | B34: 圈存 | C34: * | D34: 0 | E34: 0 | F34: 10000 | G34: 11279.4 | H34: 金武义城北加油站 | I34: 武义县武阳镇毛衣弄口
A35: 2025-01-09 22:07:39 | B35: 加油 | C35: 95号车用汽油(VIB) | D35: 34.11 | E35: 7.94 | F35: 270.83 | G35: 11008.57 | H35: 金武义城北加油站 | I35: 武义县武阳镇毛衣弄口
A36: 2025-01-21 17:46:07 | B36: 加油 | C36: 95号车用汽油(VIB) | D36: 43.67 | E36: 8.23 | F36: 359.4 | G36: 10649.17 | H36: 金武义履坦加油站 | I36: 浙江省武义县履坦镇履三村下枫树脚
A37: 2025-02-03 12:13:56 | B37: 加油 | C37: 95号车用汽油(VIB) | D37: 46.94 | E37: 8.23 | F37: 386.32 | G37: 10262.85 | H37: 金兰溪马公滩加油站 | I37: 兰溪市46省道横山村
A38: 2025-02-12 12:54:05 | B38: 加油 | C38: 95号车用汽油(VIB) | D38: 39.52 | E38: 8.23 | F38: 325.24 | G38: 9937.61 | H38: 高温丽武义服务区下 | I38: 金华市武义桐琴镇金丽温高速公路武义服务区加油站
A39: 2025-02-28 09:27:24 | B39: 加油 | C39: 95号车用汽油(VIB) | D39: 43.01 | E39: 8.09 | F39: 347.95 | G39: 9589.66 | H39: 金武义履坦加油站 | I39: 浙江省武义县履坦镇履三村下枫树脚
A40: 2025-03-08 15:09:52 | B40: 加油 | C40: 95号车用汽油(VIB) | D40: 43.38 | E40: 7.97 | F40: 345.73 | G40: 9243.93 | H40: 金婺城金兰加油站 | I40: 金华市金东区白龙桥镇王路荡村
A41: 2025-03-29 16:20:15 | B41: 加油 | C41: 95号车用汽油(VIB) | D41: 45.55 | E41: 7.73 | F41: 352.1 | G41: 8891.83 | H41: 金武义履坦加油站 | I41: 浙江省武义县履坦镇履三村下枫树脚
...

Sheet 中国石化柴汽油-汇总 
A1: 汽油车
A3: 序号 | B3: 车型 | C3: 加油类型 | D3: 2025年加油量 （升）
A4: 1 | C4: 92号车用汽油(VIB) | D4: 6056.38
A5: 2 | C5: 95号车用汽油(VIB) | D5: 12376.2
A6: 3 | C6: 爱跑98号车用汽油(VIB) | D6: 725.71
C7: 合计 | D7: 19158.29
A9: 柴油车
A11: 序号 | B11: 车型 | C11: 车牌号 | D11: 2025年加油量 （升）
A12: 1 | B12: 工具箱式车 | C12: 浙GJ2T69（0号车用柴油VI) | D12: 4106.76
C13: 合计 | D13: 4106.76

Sheet 灭火器清单
A1: 消防器材年度统计表 | G1: 消防器材统计表（明细）
A2: 类别 | B2: 2021年 | C2: 2022年 | D2: 2024年 | E2: 2025年 | G2: 一、2021年灭火器统计
A3: 干粉灭火器（个） | B3: 309 | C3: 335 | D3: 342 | E3: 342 | G3: 序号 | H3: 名称 | I3: 位置 | J3: 干粉（个） | K3: 水基（个） | L3: 二氧化碳 | M3: 备注
A4: 水基灭火器（个） | B4: 171 | C4: 179 | D4: 189 | E4: 189 | G4: 1 | H4: 灭火器 | I4: 1楼 | J4: 125 | K4: 38
A5: 二氧化碳灭火器（个） | B5: 3 | C5: 11 | G5: 2 | H5: 灭火器 | I5: 2楼 | J5: 80 | K5: 68
A6: 总计（个） | B6: 480 | C6: 514 | D6: 531 | E6: 531 | G6: 3 | H6: 灭火器 | I6: 3楼 | J6: 80 | K6: 62
A7: 同比增长 | B7: — | C7: 0.070833333 | D7: 0.093385214 | E7: 0 | G7: 4 | H7: 灭火器 | I7: 其它 | J7: 24 | K7: 0
G8: 5 | H8: 灭火器 | I8: 8组 | K8: 3
G9: 合计 | J9: 309 | K9: 171 | M9: 总计480
G11: 二、2022年灭火器统计
G12: 序号 | H12: 名称 | I12: 位置 | J12: 干粉（个） | K12: 水基（个） | L12: 二氧化碳 | M12: 备注
G13: 1 | H13: 灭火器 | I13: 1楼 | J13: 125 | K13: 38
G14: 2 | H14: 灭火器 | I14: 2楼 | J14: 106 | K14: 68
G15: 3 | H15: 灭火器 | I15: 3楼 | J15: 80 | K15: 62
G16: 4 | H16: 灭火器 | I16: 其它 | J16: 24 | K16: 0
G17: 5 | H17: 灭火器 | I17: 8组 | K17: 11
G18: 合计 | J18: 335 | K18: 179 | M18: 总计514
G20: 三、2024年消防器材统计
G21: 序号 | H21: 名称 | I21: 位置 | J21: 干粉（个） | K21: 水基（个） | L21: 二氧化碳 | M21: 备注
G22: 1 | H22: 消火栓 | I22: 车间66只外围6只
G23: 2 | H23: 灭火器 | I23: 1楼 | J23: 125 | K23: 38
G24: 3 | H24: 灭火器 | I24: 2楼 | J24: 106 | K24: 68
G25: 4 | H25: 灭火器 | I25: 3楼 | J25: 80 | K25: 62
G26: 5 | H26: 灭火器 | I26: 其它 | J26: 24
G27: 6 | H27: 灭火器 | I27: 8组 | L27: 6
G28: 7 | H28: 灭火器 | I28: 2楼锂电 | K28: 18 | M28: 2号保淋2
G29: 8 | H29: 灭火器 | I29: 出货平台 | J29: 3 | K29: 3
G30: 9 | H30: 灭火器 | I30: 2楼成品区 | J30: 4
G31: 总量 | J31: 342 | K31: 189 | M31: 总计531
G34: 四、2025年消防器材统计
G35: 序号 | H35: 名称 | I35: 位置 | J35: 干粉（个） | K35: 水基（个） | L35: 二氧化碳 | M35: 备注
G36: 1 | H36: 灭火器 | I36: 1楼 | J36: 125 | K36: 38 | M36: 换新
G37: 2 | H37: 灭火器 | I37: 2楼 | J37: 106 | K37: 68 | M37: 换新
G38: 3 | H38: 灭火器 | I38: 3楼 | J38: 80 | K38: 62 | M38: 换新
G39: 4 | H39: 灭火器 | I39: 其它 | J39: 24 | M39: 换新
G40: 5 | H40: 灭火器 | I40: 8组
G41: 6 | H41: 灭火器 | I41: 2楼锂电 | K41: 18 | M41: 换新
G42: 7 | H42: 灭火器 | I42: 出货平台 | J42: 3 | K42: 3 | M42: 换新
G43: 8 | H43: 灭火器 | I43: 2楼成品区 | J43: 4 | M43: 换新
G44: 14 | H44: 总量 | J44: 342 | K44: 189 | M44: 总计531

Sheet 空调制冷剂（办公）
A1: 空调制冷剂汇总统计表 | I1: 冷媒型号 | J1: GWP(AR4)参照数值 | K1: 典型使用场景
A2: 序号 | B2: 空调型号 | C2: 设备数量（台） | D2: 制冷剂型号 | E2: 单台填充量（kg） | F2: 总填充量（kg） | G2: 备注 | I2: R134a | J2: 1430 | K2: 冷水机组、部分生产设备制冷
A3: 1 | B3: 格力中央空调 | D3: 410 | F3: 110 | G3: 三个机组 | I3: R410A | J3: 2088 | K3: 办公多联机、中央空调
A4: 2 | B4: 美的1.5匹 | C4: 48 | D4: 410 | E4: 0.9 | F4: 43.2 | G4: 48台（0.9KG) | I4: R407C | J4: 1774 | K4: 中央空调
A5: 3 | B5: 美的3匹 | C5: 50 | D5: 410 | E5: 2 | F5: 100 | G5: 50台（2KG） | I5: R22 | J5: 1810 | K5: 老旧空调设备
A6: 4 | B6: 海尔5匹 | C6: 6 | D6: 410 | E6: 3.1 | F6: 18.6 | G6: 6台（3.1KG） | I6: R‑32 | J6: 675
A7: 5 | B7: 美的5匹 | C7: 15 | D7: 410 | E7: 3.1 | F7: 46.5 | G7: 15台（3.1KG）
A8: 6 | B8: 志高1.5匹 | C8: 3 | D8: 410 | E8: 0.9 | F8: 2.7 | G8: 3台（0.9KG)
A9: 7 | B9: 科龙3匹 | C9: 8 | D9: 410 | E9: 2 | F9: 16 | G9: 8台（2KG）
A10: 8 | B10: TCL3匹 | C10: 3 | D10: 410 | E10: 2 | F10: 6 | G10: 3台（2KG）
A11: 9 | B11: 志高3匹 | C11: 8 | D11: 410 | E11: 2 | F11: 164.3 | G11: 8台（2KG）
A12: 10 | B12: 海信5匹 | C12: 53 | D12: 410 | E12: 3.1 | F12: 164.3 | G12: 53台（3.1KG）
A13: 11 | B13: 海信3匹 | C13: 5 | D13: 410 | E13: 2 | F13: 10 | G13: 5台（2KG）
B14: 合计 | C14: 199 | F14: 423.3
A15: 空调制冷剂新增记录表
A16: 序号 | B16: 制冷剂型号 | C16: 设备名称/使用位置 | D16: 品牌 | E16: 单瓶净含量(kg) | F16: 数量(瓶) | G16: 总加注量(kg) | H16: GWP值 | I16: 备注
A17: 1 | B17: R-32 | C17: 办公空调 | D17: 中化金冷 | E17: 9 | F17: 9 | G17: 90 | H17: 675 | I17: 钢瓶标称9kg/瓶，2025年更换9瓶，实际共加注90kg
A19: 合计 | G19: =SUM(G17:G18) -> 90

Sheet 制冷剂设备明细（生产）
A1: 序号 | B1: 设备名称 | C1: 数量 | D1: 制冷剂型号 | E1: 铭牌 | F1: 额定填充量 | H1: 冷媒型号 | I1: GWP(AR4)参照数值 | J1: 典型使用场景
A2: 1 | B2: 冷冻式压缩空气干燥机（螺杆空压机配套设备） | C2: 1 | D2: R410A | F2: 4.5KG | H2: R134a | I2: 1430 | J2: 冷水机组、部分生产设备制冷
A3: 2 | B3: 冷冻式压缩空气干燥机（螺杆空压机配套设备） | C3: 1 | D3: R22 | F3: / | H3: R410A | I3: 2088 | J3: 办公多联机、中央空调
A4: 3 | B4: 冷冻式压缩空气干燥机（螺杆空压机配套设备） | C4: 1 | D4: R22 | F4: / | H4: R407C | I4: 1774 | J4: 中央空调
A5: 4 | B5: 工业恒温式冷水机（转子电焊机配套设备） | C5: 6 | D5: R22 | F5: / | H5: R22 | I5: 1810 | J5: 老旧空调设备
A6: 5 | B6: 冷却循环装置冷水机（定子浸漆机配套设备） | C6: 1 | D6: R22 | F6: / | H6: R‑32 | I6: 675
A7: 6 | B7: 冷却循环装置冷水机（定子浸漆机配套设备） | C7: 1 | D7: F22 | F7: /
A8: 合计 | F8: 4.5

Sheet 化粪池工时
A1: 厂区化粪池 - 工时统计表（年度横向对比）
A2: 指标 | B2: 2021年 | C2: 2022年 | D2: 2024年 | E2: 2025年
A3: 总工时（小时） | B3: 1343975 | C3: 1323548 | D3: 1670240 | E3: 1463918
A4: 月平均人数（人） | B4: 695 | C4: 676 | D4: 730 | E4: 890
A7: 总工时（小时）=车间总工时（行政部提供）+间接人员实际出勤天数×8h（间接人员每天按8小时计算） 平均人数（人）=一年总人数（包含临时工人数）/️12月 全年月平均人数=各月平均人数累加后除以 12；月平均人数采用（月初在岗人数 + 月末在岗人数）/2 计算

Sheet 用电量统计
A1: 用电量统计
A2: 一、2021年用电量（聚杰电度）
A3: 月份 | B3: 用电量（度） | C3: 电费金额（含税，元） | D3: 单价（元/度）
A4: 1月份 | B4: 252399 | C4: 198458.34 | D4: =IF(B4=0,"",C4/B4) -> 0.78628814
A5: 2月份 | B5: 98189.85 | C5: 90523.74 | D5: =IF(B5=0,"",C5/B5) -> 0.92192564
A6: 3月份 | B6: 307492 | C6: 239415.27 | D6: =IF(B6=0,"",C6/B6) -> 0.7786065
A7: 4月份 | B7: 305036 | C7: 239932.46 | D7: =IF(B7=0,"",C7/B7) -> 0.78657096
A8: 5月份 | B8: 314458 | C8: 237391.1 | D8: =IF(B8=0,"",C8/B8) -> 0.75492148
A9: 6月份 | B9: 327511 | C9: 241459.53 | D9: =IF(B9=0,"",C9/B9) -> 0.73725624
A10: 7月份 | B10: 339253 | C10: 258464.56 | D10: =IF(B10=0,"",C10/B10) -> 0.76186374
A11: 8月份 | B11: 347922 | C11: 268137.45 | D11: =IF(B11=0,"",C11/B11) -> 0.77068265
A12: 9月份 | B12: 292688 | C12: 227652.92 | D12: =IF(B12=0,"",C12/B12) -> 0.77780066
A13: 10月份 | B13: 257589 | C13: 216136.2 | D13: =IF(B13=0,"",C13/B13) -> 0.83907387
A14: 11月份 | B14: 275999 | C14: 237628.39 | D14: =IF(B14=0,"",C14/B14) -> 0.86097555
A15: 12月份 | B15: 296576 | C15: 303760.2 | D15: =IF(B15=0,"",C15/B15) -> 1.0242238
A16: 合计 | B16: 3415112.9 | C16: 2758960.2
A18: 二、2022年用电量（聚杰电度）
A19: 月份 | B19: 用电量（度） | C19: 电费金额（含税，元） | D19: 单价（元/度）
A20: 1月份 | B20: 270990 | C20: 265428.38 | D20: =IF(B20=0,"",C20/B20) -> 0.97947666
A21: 2月份 | B21: 153060 | C21: 163668.33 | D21: =IF(B21=0,"",C21/B21) -> 1.0693083
A22: 3月份 | B22: 317758 | C22: 312406.8 | D22: =IF(B22=0,"",C22/B22) -> 0.98315951
A23: 4月份 | B23: 290715 | C23: 308633.14 | D23: =IF(B23=0,"",C23/B23) -> 1.0616347
A24: 5月份 | B24: 283396 | C24: 273028.85 | D24: =IF(B24=0,"",C24/B24) -> 0.96341815
A25: 6月份 | B25: 246689 | C25: 249746.98 | D25: =IF(B25=0,"",C25/B25) -> 1.0123961
A26: 7月份 | B26: 323596 | C26: 297942.79 | D26: =IF(B26=0,"",C26/B26) -> 0.92072456
A27: 8月份 | B27: 344751 | C27: 338493.65 | D27: =IF(B27=0,"",C27/B27) -> 0.98184966
A28: 9月份 | B28: 241569 | C28: 240271.52 | D28: =IF(B28=0,"",C28/B28) -> 0.99462894
A29: 10月份 | B29: 134804 | C29: 153951.28 | D29: =IF(B29=0,"",C29/B29) -> 1.1420379
A30: 11月份 | B30: 162266 | C30: 171698.21 | D30: =IF(B30=0,"",C30/B30) -> 1.0581281
A31: 12月份 | B31: 329662 | C31: 316210.76 | D31: =IF(B31=0,"",C31/B31) -> 0.95919686
A32: 合计 | B32: 3099256 | C32: 3091480.7
A34: 三、2025年分表用电量
A35: 月份 | B35: 总度数 | C35: 陈杰新 | D35: 王文胜 | E35: 星河 | F35: 食堂 | G35: 聚杰
A36: 1-2月 | B36: 462540 | C36: 32245 | D36: 53020 | E36: 13375.2 | F36: 6399 | G36: 357500.8
A37: 3月 | B37: 365640 | C37: 14573 | D37: 23610 | E37: 3792 | F37: 2721 | G37: 320944
A38: 4月 | B38: 304770 | C38: 13571 | D38: 22670 | E38: 5430 | F38: 2427 | G38: 260672
A39: 5月 | B39: 255240 | C39: 14591 | D39: 12960 | E39: 4798.8 | F39: 2601 | G39: 220289.2
A40: 6月 | B40: 261900 | C40: 19266 | D40: 13880 | E40: 3614.4 | F40: 3654 | G40: 221485.6
A41: 7月 | B41: 355740 | C41: 18108 | D41: 16430 | E41: 4221.6 | F41: 5445.3 | G41: 311535.1
A42: 8月 | B42: 377010 | C42: 15658 | D42: 21330 | E42: 4064.4 | F42: 6119.7 | G42: 329837.9
...

Sheet 私车公用
A1: 私车公用补贴费用统计表
A2: 一、月度明细 - 2021年
A3: 月份 | B3: 公里数 | C3: 费用合计（元） | D3: 单价（元/公里） | E3: 备注
A4: 1月 | B4: 8234 | C4: 7855 | D4: =IF(B4=0,"",C4/B4) -> 0.95397134
A5: 2月 | B5: 9640 | C5: 9574 | D5: =IF(B5=0,"",C5/B5) -> 0.99315353
A6: 3月 | B6: 16776 | C6: 15869 | D6: =IF(B6=0,"",C6/B6) -> 0.94593467
A7: 4月 | B7: 16027 | C7: 15656 | D7: =IF(B7=0,"",C7/B7) -> 0.97685156
A8: 5月 | B8: 14314 | C8: 14059 | D8: =IF(B8=0,"",C8/B8) -> 0.98218527
A9: 6月 | B9: 16324 | C9: 16070 | D9: =IF(B9=0,"",C9/B9) -> 0.98444009
A10: 7月 | B10: 12277 | C10: 12340 | D10: =IF(B10=0,"",C10/B10) -> 1.0051315
A11: 8月 | B11: 12236 | C11: 12039 | D11: =IF(B11=0,"",C11/B11) -> 0.98389997
A12: 9月 | B12: 10451 | C12: 9869 | D12: =IF(B12=0,"",C12/B12) -> 0.94431155
A13: 10月 | B13: 10417 | C13: 10075 | D13: =IF(B13=0,"",C13/B13) -> 0.96716905
A14: 11月 | B14: 10417 | C14: 10417 | D14: =IF(B14=0,"",C14/B14) -> 1
A15: 12月 | B15: 10381 | C15: 10157 | D15: =IF(B15=0,"",C15/B15) -> 0.97842212
A16: 合计 | B16: 147494 | C16: 143980
A18: 二、月度明细 - 2022年
A19: 月份 | B19: 公里数 | C19: 费用合计（元） | D19: 单价（元/公里） | E19: 备注
A20: 1月 | B20: 6097 | C20: 6002 | D20: =IF(B20=0,"",C20/B20) -> 0.98441857
A21: 2月 | B21: 6285 | C21: 6205 | D21: =IF(B21=0,"",C21/B21) -> 0.98727128
A22: 3月 | B22: 10733 | C22: 16053 | D22: =IF(B22=0,"",C22/B22) -> 1.4956676
A23: 4月 | B23: 8280 | C23: 8227 | D23: =IF(B23=0,"",C23/B23) -> 0.99359903
A24: 5月 | B24: 5620 | C24: 5591 | D24: =IF(B24=0,"",C24/B24) -> 0.99483986
A25: 6月 | B25: 9139 | C25: 8898 | D25: =IF(B25=0,"",C25/B25) -> 0.9736295
A26: 7月 | B26: 7623 | C26: 7387 | D26: =IF(B26=0,"",C26/B26) -> 0.96904106
A27: 8月 | B27: 9007 | C27: 8667 | D27: =IF(B27=0,"",C27/B27) -> 0.96225158
A28: 9月 | B28: 10876 | C28: 9907 | D28: =IF(B28=0,"",C28/B28) -> 0.91090474
A29: 10月 | B29: 9101 | C29: 8250 | D29: =IF(B29=0,"",C29/B29) -> 0.90649379
A30: 11月 | B30: 9540 | C30: 9062 | D30: =IF(B30=0,"",C30/B30) -> 0.94989518
A31: 12月 | B31: 10266 | C31: 15193 | D31: =IF(B31=0,"",C31/B31) -> 1.4799338
A32: 合计 | B32: 102567 | C32: 109442
A34: 三、历年费用汇总（公里数）
A35: 年份 | B35: 1月 | C35: 2月 | D35: 3月 | E35: 4月 | F35: 5月 | G35: 6月 | H35: 7月 | I35: 8月 | J35: 9月 | K35: 10月 | L35: 11月 | M35: 12月 | N35: 合计 | O35: 汽油升数
A36: 2019年 | B36: 6421.6 | C36: 10466.3 | D36: 9231.4 | E36: 5741.8 | F36: 7478 | G36: 8741.4 | H36: 9478.6 | I36: 6777.2 | J36: 9821.48 | K36: 7936.4 | L36: 9939.4 | M36: 6997.8 | N36: 99031.38 | O36: =N36/11 -> 9002.8527
A37: 2020年 | B37: 1744.4 | C37: 7332.4 | D37: 6609.2 | E37: 11217.4 | F37: 14285.8 | G37: 10850.8 | H37: 15989 | I37: 12348.8 | J37: 9695 | K37: 12706.2 | L37: 15391.4 | M37: 16003.4 | N37: 134173.8 | O37: =N37/11 -> 12197.618
A38: 2021年 | B38: 7855.4 | C38: 9574.6 | D38: 15869.8 | E38: 15656.4 | F38: 13836.2 | G38: 15846.4 | H38: 12289.6 | I38: 11962.8 | J38: 9870.6 | K38: 10160.4 | L38: 10160.4 | M38: 9999 | N38: 143081.6 | O38: =N38/11 -> 13007.418
A39: 2022年 | B39: 6071 | C39: 6205 | D39: 10380.8 | E39: 8227 | F39: 5591.4 | G39: 8898.4 | H39: 7387.8 | I39: 8667.2 | J39: 9908 | K39: 8250.8 | L39: 9062.4 | M39: 15193.8 | N39: 103843.6 | O39: =N39/11 -> 9440.3273
A40: 2023年 | B40: 5740.6 | C40: 13685.8 | D40: 13847.2 | E40: 27571.2 | F40: 14383.8 | G40: 25272 | H40: 22850.6 | I40: 16426.6 | J40: 20458.8 | K40: 17142.4 | L40: 16964 | M40: 13440.8 | N40: 207783.8 | O40: =N40/11 -> 18889.436
A41: 2024年 | B41: 19041.4 | C41: 8113.4 | D41: 14158.2 | E41: 19476.4 | F41: 20014.8 | G41: 20134 | H41: 19778.2 | I41: 20462.2 | J41: 17980.4 | K41: 19257.8 | L41: 18211.6 | M41: 8191.2 | N41: 204819.6 | O41: =N41/11 -> 18619.964
A42: 2025年 | B42: 16776.2 | C42: 11720.2 | D42: 20134.8 | E42: 10999.6 | F42: 13697.4 | G42: 14595 | H42: 12222.4 | I42: 12222.4 | J42: 14421 | K42: 14095 | L42: 13216.8 | M42: 16444.6 | N42: 170545.4 | O42: =N42/11 -> 15504.127
...

Sheet 供电局电费明细
A1: 供电局电费明细表
A2: 月份 | B2: 用电类型 | C2: 用电度数 | D2: 用电金额（元） | E2: 单价（元/度） | F2: 基本电费（元） | G2: 力调电费（元） | H2: 开票金额（元）
A3: 1月 | B3: 尖电 | C3: 133770 | D3: 160269.41 | E3: 1.1980968 | F3: 33900 | G3: 2351.54 | H3: 327408.77
A4: 1月 | B4: 峰电 | C4: 99930 | D4: 96533.151 | E4: 0.96600771
A5: 1月 | B5: 谷电 | C5: 128880 | D5: 38959.305 | E5: 0.30229132
A6: 1月 | B6: 最终金额 | C6: 362580 | D6: 295761.87 | E6: 0.90272583 | G6: 327310.33
A7: 2月 | B7: 尖电 | C7: 34050 | D7: 41456.305 | E7: 1.2175126 | F7: 33900 | G7: 916.57 | H7: 130717.67
A8: 2月 | B8: 峰电 | C8: 44850 | D8: 44602.339 | E8: 0.99447801
A9: 2月 | B9: 谷电 | C9: 39000 | D9: 11659.596 | E9: 0.298964
A10: 2月 | B10: 最终金额 | C10: 117900 | D10: 97718.24 | E10: 1.1085807 | G10: 130701.67
A11: 3月 | B11: 峰电 | C11: 144733 | D11: 167245.32 | E11: 1.1555438
A12: 3月 | B12: 平电 | C12: 87368 | D12: 58998.975 | E12: 0.67529273
A13: 3月 | B13: 谷电 | C13: 102309 | D13: 30293.883 | E13: 0.29610184
A14: 3月 | B14: 最终金额 | C14: 334410 | D14: 256538.18 | E14: 0.86247463 | G14: 288420.14
A15: 4月 | B15: 峰电 | C15: 151080 | D15: 182701.03 | E15: 1.2092999
A16: 4月 | B16: 平电 | C16: 97620 | D16: 68926.724 | E16: 0.70607174
A17: 4月 | B17: 谷电 | C17: 109530 | D17: 33905.652 | E17: 0.30955585
A18: 4月 | B18: 最终金额 | C18: 358230 | D18: 285533.41 | E18: 0.88570575 | G18: 317286.37
A19: 5月 | B19: 峰电 | C19: 142002 | D19: 169985.6 | E19: 1.1970648
A20: 5月 | B20: 平电 | C20: 99909 | D20: 70033.376 | E20: 0.70097164
A21: 5月 | B21: 谷电 | C21: 92888 | D21: 28806.493 | E21: 0.31012071
A22: 5月 | B22: 最终金额 | C22: 334799 | D22: 268825.47 | E22: 0.89594318 | G22: 299960.88
A23: 6月 | B23: 峰电 | C23: 187860 | D23: 210174.96 | E23: 1.1187851
A24: 6月 | B24: 平电 | C24: 112530 | D24: 73513.101 | E24: 0.65327558
A25: 6月 | B25: 谷电 | C25: 124350 | D25: 35584.788 | E25: 0.28616637
A26: 6月 | B26: 最终金额 | C26: 424740 | D26: 319272.85 | E26: 0.82562841 | G26: 350677.41
A27: 7月 | B27: 尖电 | C27: 130059 | D27: 172833.3 | E27: 1.3288838 | F27: 38448.39 | G27: 3494.82 | H27: 497661.82
A28: 7月 | B28: 峰电 | C28: 168902 | D28: 193117.24 | E28: 1.1433686
A29: 7月 | B29: 谷电 | C29: 244459 | D29: 93666.009 | E29: 0.38315631
A30: 7月 | B30: 最终金额 | C30: 543420 | D30: 459616.55 | E30: 0.91010658 | G30: 494570.12
A31: 8月 | B31: 尖电 | C31: 118597 | D31: 157999.24 | E31: 1.3322364 | F31: 48000 | G31: 3213.92 | H31: 455526.57
A32: 8月 | B32: 峰电 | C32: 151990 | D32: 173199.24 | E32: 1.1395437
A33: 8月 | B33: 谷电 | C33: 205753 | D33: 79455.905 | E33: 0.38617131
A34: 8月 | B34: 最终金额 | C34: 476340 | D34: 410654.39 | E34: 0.95612476 | G34: 455440.47
A35: 9月 | B35: 峰电 | C35: 175753 | D35: 198025.74 | E35: 1.1267275
A36: 9月 | B36: 平电 | C36: 104798 | D36: 70745.151 | E36: 0.67506203
A37: 9月 | B37: 谷电 | C37: 112329 | D37: 33834.178 | E37: 0.30120608
A38: 9月 | B38: 最终金额 | C38: 392880 | D38: 302605.07 | E38: 0.80002523 | G38: 314313.91
A39: 10月 | B39: 峰电 | C39: 129240 | D39: 147537.95 | E39: 1.1415811
A40: 10月 | B40: 平电 | C40: 83910 | D40: 56369.189 | E40: 0.67178155
...

Sheet 成品运输-工厂
A1: 序号 | B1: 发货日期 | C1: 客户简称 | D1: 出口国家 | E1: 送货地点 | F1: 运输距离 | G1: 箱数 | H1: 重量 | I1: 立方数 | J1: 单次油耗 | K1: 吨·公里
A2: 1 | B2: 2025-01-02 | C2: 翠丰 | D2: 土耳其 | E2: 宁波 | F2: 320 | G2: 150 | H2: 2325 | I2: 6.34 | J2: =SUMPRODUCT(0.01375,F2,H2/1000) -> 10.23 | K2: =SUMPRODUCT(F2,H2/1000) -> 744
A3: 2 | B3: 2025-01-02 | C3: 翠丰 | D3: 土耳其 | E3: 宁波 | F3: 320 | G3: 300 | H3: 6600 | I3: 18.27 | J3: =SUMPRODUCT(0.01375,F3,H3/1000) -> 29.04 | K3: =SUMPRODUCT(F3,H3/1000) -> 2112
A4: 3 | B4: 2025-01-02 | C4: ADEO | D4: 法国 | E4: 宁波 | F4: 320 | G4: 54 | H4: 755.13 | I4: 1.027 | J4: =SUMPRODUCT(0.01375,F4,H4/1000) -> 3.322572 | K4: =SUMPRODUCT(F4,H4/1000) -> 241.6416
A5: 4 | B5: 2025-01-03 | C5: TTI | D5: 荷兰 | E5: 上海 | F5: 320 | G5: 88 | H5: 924 | I5: 3.278 | J5: =SUMPRODUCT(0.01375,F5,H5/1000) -> 4.0656 | K5: =SUMPRODUCT(F5,H5/1000) -> 295.68
A6: 5 | B6: 2025-01-03 | C6: TTI | D6: 荷兰 | E6: 上海 | F6: 320 | G6: 177 | H6: 2035.5 | I6: 6.593 | J6: =SUMPRODUCT(0.01375,F6,H6/1000) -> 8.9562 | K6: =SUMPRODUCT(F6,H6/1000) -> 651.36
A7: 6 | B7: 2025-01-03 | C7: TTI | D7: 法国 | E7: 上海 | F7: 320 | G7: 63 | H7: 1260 | I7: 5.715 | J7: =SUMPRODUCT(0.01375,F7,H7/1000) -> 5.544 | K7: =SUMPRODUCT(F7,H7/1000) -> 403.2
A8: 7 | B8: 2025-01-03 | C8: 德国SCHEPPACH | D8: 德国 | E8: 宁波 | F8: 320 | G8: 710 | H8: 15265 | I8: 27.6 | J8: =SUMPRODUCT(0.01375,F8,H8/1000) -> 67.166 | K8: =SUMPRODUCT(F8,H8/1000) -> 4884.8
A9: 8 | B9: 2025-01-03 | C9: Elite Production and Trading Group | D9: 伊朗 | E9: 宁波 | F9: 320 | G9: 250 | H9: 5000 | I9: 11.54 | J9: =SUMPRODUCT(0.01375,F9,H9/1000) -> 22 | K9: =SUMPRODUCT(F9,H9/1000) -> 1600
A10: 9 | B10: 2025-01-03 | C10: Elite Production and Trading Group | D10: 伊朗 | E10: 宁波 | F10: 320 | G10: 250 | H10: 5200 | I10: 13.34 | J10: =SUMPRODUCT(0.01375,F10,H10/1000) -> 22.88 | K10: =SUMPRODUCT(F10,H10/1000) -> 1664
A11: 10 | B11: 2025-01-03 | C11: Elite Production and Trading Group | D11: 伊朗 | E11: 宁波 | F11: 320 | G11: 10 | H11: 119 | I11: 0.26 | J11: =SUMPRODUCT(0.01375,F11,H11/1000) -> 0.5236 | K11: =SUMPRODUCT(F11,H11/1000) -> 38.08
A12: 11 | B12: 2025-01-03 | C12: Elite Production and Trading Group | D12: 伊朗 | E12: 宁波 | F12: 320 | G12: 11 | H12: 120 | I12: 0.24 | J12: =SUMPRODUCT(0.01375,F12,H12/1000) -> 0.528 | K12: =SUMPRODUCT(F12,H12/1000) -> 38.4
A13: 12 | B13: 2025-01-04 | C13: TTI | D13: 越南 | E13: 宁波 | F13: 320 | G13: 16 | H13: 240 | I13: 0.25 | J13: =SUMPRODUCT(0.01375,F13,H13/1000) -> 1.056 | K13: =SUMPRODUCT(F13,H13/1000) -> 76.8
... A1681: 1680 | B1681: 2025-12-31 | C1681: YANDEX MARKET.TRADE LLC | D1681: 俄罗斯 | E1681: 宁波 | F1681: 320 | G1681: 62.5 | H1681: 937.5 | I1681: 2.75 | J1681: =SUMPRODUCT(0.01375,F1681,H1681/1000) -> 4.125 | K1681: =SUMPRODUCT(F1681,H1681/1000) -> 300
A1686: 序号 | B1686: 发货日期 | C1686: 客户简称 | D1686: 出口国家 | E1686: 送货地点 | F1686: 运输距离 | G1686: 箱数 | H1686: 重量 | I1686: 立法数 | J1686: 单次油耗 | K1686: 吨·公里
A1687: 总计 | B1687: 2025-01-02——2025-12-31 | C1687: 不定 | D1687: 不定 | E1687: 不定 | F1687: 516790 | G1687: 441056.36 | H1687: 7027843.4 | I1687: 19939.8260000001 | J1687: 30040.042937575 | K1687: 2184730.4
A1689: 吨•公里=运输距离×（重量/1000)
A1690: 单次油耗=0.01375×运输距离×（重量/1000)

Sheet 成品运输-外购
A1: 序号 | B1: 发货日期 | C1: 客户简称 | D1: 出口国家 | E1: 送货地点 | F1: 运输距离 | G1: 箱数 | H1: 重量 | I1: 立方数 | J1: 单次油耗 | K1: 吨·公里
A2: 1 | B2: 2025-01-10 | C2: 芬兰TOKMANNI | D2: 芬兰 | E2: 宁波 | F2: 320 | G2: 151 | H2: 1389.2 | I2: 9.53 | J2: =SUMPRODUCT(0.01375,F2,H2/1000) -> 6.11248 | K2: =SUMPRODUCT(F2,H2/1000) -> 444.544
A3: 2 | B3: 2025-01-10 | C3: 芬兰TOKMANNI | D3: 芬兰 | E3: 宁波 | F3: 320 | G3: 60 | H3: 1380 | I3: 3.07 | J3: =SUMPRODUCT(0.01375,F3,H3/1000) -> 6.072 | K3: =SUMPRODUCT(F3,H3/1000) -> 441.6
A4: 3 | B4: 2025-01-11 | C4: ADEO | D4: 法国 | E4: 宁波 | F4: 320 | G4: 480 | H4: 4828.8 | I4: 14.36 | J4: =SUMPRODUCT(0.01375,F4,H4/1000) -> 21.24672 | K4: =SUMPRODUCT(F4,H4/1000) -> 1545.216
A5: 4 | B5: 2025-01-13 | C5: ADEO | D5: 法国 | E5: 宁波 | F5: 320 | G5: 280 | H5: 5390 | I5: 14.68 | J5: =SUMPRODUCT(0.01375,F5,H5/1000) -> 23.716 | K5: =SUMPRODUCT(F5,H5/1000) -> 1724.8
A6: 5 | B6: 2025-01-15 | C6: 哈萨克斯坦TSSP | D6: 哈萨克斯坦 | E6: 义乌 | F6: 50 | G6: 64 | H6: 1216 | I6: 3.596 | J6: =SUMPRODUCT(0.01375,F6,H6/1000) -> 0.836 | K6: =SUMPRODUCT(F6,H6/1000) -> 60.8
A7: 6 | B7: 2025-02-11 | C7: ADEO | D7: 法国 | E7: 宁波 | F7: 320 | G7: 250 | H7: 4812.5 | I7: 13.1 | J7: =SUMPRODUCT(0.01375,F7,H7/1000) -> 21.175 | K7: =SUMPRODUCT(F7,H7/1000) -> 1540
A8: 7 | B8: 2025-02-11 | C8: ADEO | D8: 法国 | E8: 宁波 | F8: 320 | G8: 1250 | H8: 12575 | I8: 37.39 | J8: =SUMPRODUCT(0.01375,F8,H8/1000) -> 55.33 | K8: =SUMPRODUCT(F8,H8/1000) -> 4024
A9: 8 | B9: 2025-03-15 | C9: 上海震坤行 | D9: 美国 | E9: 嘉兴 | F9: 300 | G9: 30 | H9: 570 | I9: 1.55 | J9: =SUMPRODUCT(0.01375,F9,H9/1000) -> 2.35125 | K9: =SUMPRODUCT(F9,H9/1000) -> 171
A10: 9 | B10: 2025-03-28 | C10: 上海震坤行 | D10: 美国 | E10: 嘉兴 | F10: 300 | G10: 42 | H10: 798 | I10: 2.17 | J10: =SUMPRODUCT(0.01375,F10,H10/1000) -> 3.29175 | K10: =SUMPRODUCT(F10,H10/1000) -> 239.4
A11: 10 | B11: 2025-03-14 | C11: ADEO | D11: 法国 | E11: 宁波 | F11: 320 | G11: 499 | H11: 9605.75 | I11: 26.16 | J11: =SUMPRODUCT(0.01375,F11,H11/1000) -> 42.2653 | K11: =SUMPRODUCT(F11,H11/1000) -> 3073.84
A12: 11 | B12: 2025-03-14 | C12: ADEO | D12: 法国 | E12: 宁波 | F12: 320 | G12: 197 | H12: 1981.82 | I12: 5.89 | J12: =SUMPRODUCT(0.01375,F12,H12/1000) -> 8.720008 | K12: =SUMPRODUCT(F12,H12/1000) -> 634.1824
A13: 12 | B13: 2025-04-02 | C13: SCHMITH | D13: 波兰 | E13: 宁波 | F13: 320 | G13: 50 | H13: 1175 | I13: 3.1 | J13: =SUMPRODUCT(0.01375,F13,H13/1000) -> 5.17 | K13: =SUMPRODUCT(F13,H13/1000) -> 376
... A99: 98 | B99: 2025-12-15 | C99: ADEO | D99: 法国 | E99: 宁波 | F99: 320 | G99: 750 | H99: 16950 | I99: 63.16 | J99: =SUMPRODUCT(0.01375,F99,H99/1000) -> 74.58 | K99: =SUMPRODUCT(F99,H99/1000) -> 5424
A102: 序号 | B102: 发货日期 | C102: 客户简称 | D102: 出口国家 | E102: 送货地点 | F102: 运输距离 | G102: 箱数 | H102: 重量 | I102: 立法数 | J102: 单次油耗 | K102: 吨·公里
A103: 总计 | B103: 2025-01-02——2025-12-31 | C103: 不定 | D103: 不定 | E103: 不定 | F103: 30510 | G103: 26338 | H103: 433241.59 | I103: 1442.065 | J103: 1901.2514 | K103: 138272.83
A105: 吨•公里=运输距离×（重量/1000)
A106: 单次油耗=0.01375×运输距离×（重量/1000)

Sheet 成品运输-汇总
A1: 序号 | B1: 发货日期 | C1: 客户简称 | D1: 出口国家 | E1: 送货地点 | F1: 运输距离 | G1: 箱数 | H1: 重量 | I1: 立法数 | J1: 单次油耗 | K1: 吨·公里
A2: 总计 | B2: 2025-01-02——2025-12-31 | C2: 不定 | D2: 不定 | E2: 不定 | F2: 516790 | G2: 441056.36 | H2: 7027843.4 | I2: 19939.8260000001 | J2: 30040.042937575 | K2: 2184730.4
A4: 吨•公里=运输距离×（重量/1000)
A5: 单次油耗=0.01375×运输距离×（重量/1000)
A8: 序号 | B8: 发货日期 | C8: 客户简称 | D8: 出口国家 | E8: 送货地点 | F8: 运输距离 | G8: 箱数 | H8: 重量 | I8: 立法数 | J8: 单次油耗 | K8: 吨·公里
A9: 总计 | B9: 2025-01-02——2025-12-31 | C9: 不定 | D9: 不定 | E9: 不定 | F9: 30510 | G9: 26338 | H9: 433241.59 | I9: 1442.065 | J9: 1901.2514 | K9: 138272.83
A12: 工厂+外购 | B12: =K9+K2 -> 2323003.2
